Traceback (most recent call last):
  File "/home/kegedy/anaconda3/lib/python3.7/site-packages/jupyter_cache/executors/utils.py", line 56, in single_nb_execution
    record_timing=False,
  File "/home/kegedy/anaconda3/lib/python3.7/site-packages/nbclient/client.py", line 1204, in execute
    return NotebookClient(nb=nb, resources=resources, km=km, **kwargs).execute()
  File "/home/kegedy/anaconda3/lib/python3.7/site-packages/nbclient/util.py", line 84, in wrapped
    return just_run(coro(*args, **kwargs))
  File "/home/kegedy/anaconda3/lib/python3.7/site-packages/nbclient/util.py", line 62, in just_run
    return loop.run_until_complete(coro)
  File "/home/kegedy/anaconda3/lib/python3.7/asyncio/base_events.py", line 587, in run_until_complete
    return future.result()
  File "/home/kegedy/anaconda3/lib/python3.7/site-packages/nbclient/client.py", line 664, in async_execute
    cell, index, execution_count=self.code_cells_executed + 1
  File "/home/kegedy/anaconda3/lib/python3.7/site-packages/nbclient/client.py", line 965, in async_execute_cell
    await self._check_raise_for_error(cell, cell_index, exec_reply)
  File "/home/kegedy/anaconda3/lib/python3.7/site-packages/nbclient/client.py", line 862, in _check_raise_for_error
    raise CellExecutionError.from_cell_and_msg(cell, exec_reply_content)
nbclient.exceptions.CellExecutionError: An error occurred while executing the following cell:
------------------
# Find V0
x0 = 330
V0 = Part1_unknown2[x0][0]
res = 0.05   # resolution = 0.05ns

# Time Constant
V1 = V0 + 0.632 * (2*Ei-V0)  # 0.4349
x1 = np.where((Part1_unknown2>0.43) & (Part1_unknown2<0.44))[0][0]

# Print
print(f'Initial Voltage       = {round(V0,4)}V at t = {round(x0*res,1)}ns')
print(f'System Response 1-1/e = {round(V1,4)}V at t = {round(x1*res,1)}ns')
print(f'Time Response Tau     = {round((x1-x0)*res,1)}ns')
------------------

[0;31m---------------------------------------------------------------------------[0m
[0;31mNameError[0m                                 Traceback (most recent call last)
[0;32m/tmp/ipykernel_5009/2045467097.py[0m in [0;36m<module>[0;34m[0m
[1;32m      5[0m [0;34m[0m[0m
[1;32m      6[0m [0;31m# Time Constant[0m[0;34m[0m[0;34m[0m[0;34m[0m[0m
[0;32m----> 7[0;31m [0mV1[0m [0;34m=[0m [0mV0[0m [0;34m+[0m [0;36m0.632[0m [0;34m*[0m [0;34m([0m[0;36m2[0m[0;34m*[0m[0mEi[0m[0;34m-[0m[0mV0[0m[0;34m)[0m  [0;31m# 0.4349[0m[0;34m[0m[0;34m[0m[0m
[0m[1;32m      8[0m [0mx1[0m [0;34m=[0m [0mnp[0m[0;34m.[0m[0mwhere[0m[0;34m([0m[0;34m([0m[0mPart1_unknown2[0m[0;34m>[0m[0;36m0.43[0m[0;34m)[0m [0;34m&[0m [0;34m([0m[0mPart1_unknown2[0m[0;34m<[0m[0;36m0.44[0m[0;34m)[0m[0;34m)[0m[0;34m[[0m[0;36m0[0m[0;34m][0m[0;34m[[0m[0;36m0[0m[0;34m][0m[0;34m[0m[0;34m[0m[0m
[1;32m      9[0m [0;34m[0m[0m

[0;31mNameError[0m: name 'Ei' is not defined
NameError: name 'Ei' is not defined

